2025-05-09 00:34:23,298 - INFO - Admin user created with temporary password
2025-05-09 00:34:23,619 - WARNING -  * Debugger is active!
2025-05-09 00:34:23,624 - INFO -  * Debugger PIN: 142-401-602
2025-05-09 00:34:52,805 - INFO - 127.0.0.1 - - [09/May/2025 00:34:52] "GET /login HTTP/1.1" 200 -
2025-05-09 00:34:52,963 - INFO - 127.0.0.1 - - [09/May/2025 00:34:52] "[36mGET /static/css/app.css HTTP/1.1[0m" 304 -
2025-05-09 00:34:52,977 - INFO - 127.0.0.1 - - [09/May/2025 00:34:52] "[36mGET /static/js/theme.js HTTP/1.1[0m" 304 -
2025-05-09 00:35:42,691 - INFO - 127.0.0.1 - - [09/May/2025 00:35:42] "[35m[1mPOST /login HTTP/1.1[0m" 500 -
2025-05-09 00:35:42,765 - INFO - 127.0.0.1 - - [09/May/2025 00:35:42] "GET /login?__debugger__=yes&cmd=resource&f=style.css HTTP/1.1" 200 -
2025-05-09 00:35:42,799 - INFO - 127.0.0.1 - - [09/May/2025 00:35:42] "GET /login?__debugger__=yes&cmd=resource&f=debugger.js HTTP/1.1" 200 -
2025-05-09 00:35:43,039 - INFO - 127.0.0.1 - - [09/May/2025 00:35:43] "GET /login?__debugger__=yes&cmd=resource&f=console.png&s=4PrJBgLr0YR9qRjeoa3x HTTP/1.1" 200 -
2025-05-09 00:35:43,090 - INFO - 127.0.0.1 - - [09/May/2025 00:35:43] "GET /login?__debugger__=yes&cmd=resource&f=console.png HTTP/1.1" 200 -
2025-05-09 02:25:50,392 - INFO -  * Detected change in 'D:\\Arsalan khan\\ARSALAN KHAN (UNI)\\a semester 6 spring 2025\\secure software design\\project\\-Ride-Hailing-Website-with-Integrated-Security-Features\\week4-6\\app.py', reloading
2025-05-09 02:39:18,746 - INFO - [31m[1mWARNING: This is a development server. Do not use it in a production deployment. Use a production WSGI server instead.[0m
 * Running on all addresses (0.0.0.0)
 * Running on http://127.0.0.1:5000
 * Running on http://10.1.144.62:5000
2025-05-09 02:39:18,746 - INFO - [33mPress CTRL+C to quit[0m
2025-05-09 02:39:37,288 - INFO - 127.0.0.1 - - [09/May/2025 02:39:37] "GET /login HTTP/1.1" 200 -
2025-05-09 02:39:37,416 - INFO - 127.0.0.1 - - [09/May/2025 02:39:37] "[36mGET /static/js/theme.js HTTP/1.1[0m" 304 -
2025-05-09 02:39:37,417 - INFO - 127.0.0.1 - - [09/May/2025 02:39:37] "[36mGET /static/css/app.css HTTP/1.1[0m" 304 -
2025-05-09 02:39:46,044 - ERROR - Exception on /login [POST]
Traceback (most recent call last):
  File "C:\Users\Personal\AppData\Roaming\Python\Python313\site-packages\flask\app.py", line 1511, in wsgi_app
    response = self.full_dispatch_request()
  File "C:\Users\Personal\AppData\Roaming\Python\Python313\site-packages\flask\app.py", line 919, in full_dispatch_request
    rv = self.handle_user_exception(e)
  File "C:\Users\Personal\AppData\Roaming\Python\Python313\site-packages\flask\app.py", line 917, in full_dispatch_request
    rv = self.dispatch_request()
  File "C:\Users\Personal\AppData\Roaming\Python\Python313\site-packages\flask\app.py", line 902, in dispatch_request
    return self.ensure_sync(self.view_functions[rule.endpoint])(**view_args)  # type: ignore[no-any-return]
           ~~~~~~~~~~~~~~~~~~~~~~~~~~~~~~~~~~~~~~~~~~~~~~~~~~~~^^^^^^^^^^^^^
  File "D:\Arsalan khan\ARSALAN KHAN (UNI)\a semester 6 spring 2025\secure software design\project\-Ride-Hailing-Website-with-Integrated-Security-Features\week4-6\app.py", line 99, in decorated_function
    return f(*args, **kwargs)
  File "D:\Arsalan khan\ARSALAN KHAN (UNI)\a semester 6 spring 2025\secure software design\project\-Ride-Hailing-Website-with-Integrated-Security-Features\week4-6\app.py", line 172, in login
    user = conn.execute("""
           ~~~~~~~~~~~~^^^^
        SELECT id, email, password, name, role, failed_attempts, locked_until
        ^^^^^^^^^^^^^^^^^^^^^^^^^^^^^^^^^^^^^^^^^^^^^^^^^^^^^^^^^^^^^^^^^^^^^
        FROM users WHERE email = ?
        ^^^^^^^^^^^^^^^^^^^^^^^^^^
    """, (email,)).fetchone()
    ^^^^^^^^^^^^^^
sqlite3.OperationalError: no such column: failed_attempts
2025-05-09 02:39:46,048 - INFO - 127.0.0.1 - - [09/May/2025 02:39:46] "[35m[1mPOST /login HTTP/1.1[0m" 500 -
2025-05-09 02:39:46,143 - ERROR - Exception on /favicon.ico [GET]
Traceback (most recent call last):
  File "C:\Users\Personal\AppData\Roaming\Python\Python313\site-packages\flask\app.py", line 917, in full_dispatch_request
    rv = self.dispatch_request()
  File "C:\Users\Personal\AppData\Roaming\Python\Python313\site-packages\flask\app.py", line 891, in dispatch_request
    self.raise_routing_exception(req)
    ~~~~~~~~~~~~~~~~~~~~~~~~~~~~^^^^^
  File "C:\Users\Personal\AppData\Roaming\Python\Python313\site-packages\flask\app.py", line 500, in raise_routing_exception
    raise request.routing_exception  # type: ignore[misc]
    ^^^^^^^^^^^^^^^^^^^^^^^^^^^^^^^
  File "C:\Users\Personal\AppData\Roaming\Python\Python313\site-packages\flask\ctx.py", line 362, in match_request
    result = self.url_adapter.match(return_rule=True)  # type: ignore
  File "C:\Users\Personal\AppData\Roaming\Python\Python313\site-packages\werkzeug\routing\map.py", line 629, in match
    raise NotFound() from None
werkzeug.exceptions.NotFound: 404 Not Found: The requested URL was not found on the server. If you entered the URL manually please check your spelling and try again.

During handling of the above exception, another exception occurred:

Traceback (most recent call last):
  File "C:\Users\Personal\AppData\Roaming\Python\Python313\site-packages\flask\app.py", line 1511, in wsgi_app
    response = self.full_dispatch_request()
  File "C:\Users\Personal\AppData\Roaming\Python\Python313\site-packages\flask\app.py", line 919, in full_dispatch_request
    rv = self.handle_user_exception(e)
  File "C:\Users\Personal\AppData\Roaming\Python\Python313\site-packages\flask\app.py", line 802, in handle_user_exception
    return self.handle_http_exception(e)
           ~~~~~~~~~~~~~~~~~~~~~~~~~~^^^
  File "C:\Users\Personal\AppData\Roaming\Python\Python313\site-packages\flask\app.py", line 777, in handle_http_exception
    return self.ensure_sync(handler)(e)  # type: ignore[no-any-return]
           ~~~~~~~~~~~~~~~~~~~~~~~~~^^^
  File "D:\Arsalan khan\ARSALAN KHAN (UNI)\a semester 6 spring 2025\secure software design\project\-Ride-Hailing-Website-with-Integrated-Security-Features\week4-6\app.py", line 558, in page_not_found
    return render_template('errors/404.html'), 404
           ~~~~~~~~~~~~~~~^^^^^^^^^^^^^^^^^^^
  File "C:\Users\Personal\AppData\Roaming\Python\Python313\site-packages\flask\templating.py", line 149, in render_template
    template = app.jinja_env.get_or_select_template(template_name_or_list)
  File "C:\Users\Personal\AppData\Roaming\Python\Python313\site-packages\jinja2\environment.py", line 1087, in get_or_select_template
    return self.get_template(template_name_or_list, parent, globals)
           ~~~~~~~~~~~~~~~~~^^^^^^^^^^^^^^^^^^^^^^^^^^^^^^^^^^^^^^^^
  File "C:\Users\Personal\AppData\Roaming\Python\Python313\site-packages\jinja2\environment.py", line 1016, in get_template
    return self._load_template(name, globals)
           ~~~~~~~~~~~~~~~~~~~^^^^^^^^^^^^^^^
  File "C:\Users\Personal\AppData\Roaming\Python\Python313\site-packages\jinja2\environment.py", line 975, in _load_template
    template = self.loader.load(self, name, self.make_globals(globals))
  File "C:\Users\Personal\AppData\Roaming\Python\Python313\site-packages\jinja2\loaders.py", line 126, in load
    source, filename, uptodate = self.get_source(environment, name)
                                 ~~~~~~~~~~~~~~~^^^^^^^^^^^^^^^^^^^
  File "C:\Users\Personal\AppData\Roaming\Python\Python313\site-packages\flask\templating.py", line 65, in get_source
    return self._get_source_fast(environment, template)
           ~~~~~~~~~~~~~~~~~~~~~^^^^^^^^^^^^^^^^^^^^^^^
  File "C:\Users\Personal\AppData\Roaming\Python\Python313\site-packages\flask\templating.py", line 99, in _get_source_fast
    raise TemplateNotFound(template)
jinja2.exceptions.TemplateNotFound: errors/404.html
2025-05-09 02:39:46,172 - ERROR - Error on request:
Traceback (most recent call last):
  File "C:\Users\Personal\AppData\Roaming\Python\Python313\site-packages\flask\app.py", line 1511, in wsgi_app
    response = self.full_dispatch_request()
  File "C:\Users\Personal\AppData\Roaming\Python\Python313\site-packages\flask\app.py", line 919, in full_dispatch_request
    rv = self.handle_user_exception(e)
  File "C:\Users\Personal\AppData\Roaming\Python\Python313\site-packages\flask\app.py", line 917, in full_dispatch_request
    rv = self.dispatch_request()
  File "C:\Users\Personal\AppData\Roaming\Python\Python313\site-packages\flask\app.py", line 902, in dispatch_request
    return self.ensure_sync(self.view_functions[rule.endpoint])(**view_args)  # type: ignore[no-any-return]
           ~~~~~~~~~~~~~~~~~~~~~~~~~~~~~~~~~~~~~~~~~~~~~~~~~~~~^^^^^^^^^^^^^
  File "D:\Arsalan khan\ARSALAN KHAN (UNI)\a semester 6 spring 2025\secure software design\project\-Ride-Hailing-Website-with-Integrated-Security-Features\week4-6\app.py", line 99, in decorated_function
    return f(*args, **kwargs)
  File "D:\Arsalan khan\ARSALAN KHAN (UNI)\a semester 6 spring 2025\secure software design\project\-Ride-Hailing-Website-with-Integrated-Security-Features\week4-6\app.py", line 172, in login
    user = conn.execute("""
           ^^^^^^^
sqlite3.OperationalError: no such column: failed_attempts

During handling of the above exception, another exception occurred:

Traceback (most recent call last):
  File "C:\Users\Personal\AppData\Roaming\Python\Python313\site-packages\werkzeug\serving.py", line 370, in run_wsgi
    execute(self.server.app)
    ~~~~~~~^^^^^^^^^^^^^^^^^
  File "C:\Users\Personal\AppData\Roaming\Python\Python313\site-packages\werkzeug\serving.py", line 331, in execute
    application_iter = app(environ, start_response)
  File "C:\Users\Personal\AppData\Roaming\Python\Python313\site-packages\flask\app.py", line 1536, in __call__
    return self.wsgi_app(environ, start_response)
           ~~~~~~~~~~~~~^^^^^^^^^^^^^^^^^^^^^^^^^
  File "C:\Users\Personal\AppData\Roaming\Python\Python313\site-packages\werkzeug\middleware\proxy_fix.py", line 183, in __call__
    return self.app(environ, start_response)
           ~~~~~~~~^^^^^^^^^^^^^^^^^^^^^^^^^
  File "C:\Users\Personal\AppData\Roaming\Python\Python313\site-packages\flask\app.py", line 1514, in wsgi_app
    response = self.handle_exception(e)
  File "C:\Users\Personal\AppData\Roaming\Python\Python313\site-packages\flask\app.py", line 860, in handle_exception
    server_error = self.ensure_sync(handler)(server_error)
  File "D:\Arsalan khan\ARSALAN KHAN (UNI)\a semester 6 spring 2025\secure software design\project\-Ride-Hailing-Website-with-Integrated-Security-Features\week4-6\app.py", line 562, in internal_server_error
    return render_template('errors/500.html'), 500
           ~~~~~~~~~~~~~~~^^^^^^^^^^^^^^^^^^^
  File "C:\Users\Personal\AppData\Roaming\Python\Python313\site-packages\flask\templating.py", line 149, in render_template
    template = app.jinja_env.get_or_select_template(template_name_or_list)
  File "C:\Users\Personal\AppData\Roaming\Python\Python313\site-packages\jinja2\environment.py", line 1087, in get_or_select_template
    return self.get_template(template_name_or_list, parent, globals)
           ~~~~~~~~~~~~~~~~~^^^^^^^^^^^^^^^^^^^^^^^^^^^^^^^^^^^^^^^^
  File "C:\Users\Personal\AppData\Roaming\Python\Python313\site-packages\jinja2\environment.py", line 1016, in get_template
    return self._load_template(name, globals)
           ~~~~~~~~~~~~~~~~~~~^^^^^^^^^^^^^^^
  File "C:\Users\Personal\AppData\Roaming\Python\Python313\site-packages\jinja2\environment.py", line 975, in _load_template
    template = self.loader.load(self, name, self.make_globals(globals))
  File "C:\Users\Personal\AppData\Roaming\Python\Python313\site-packages\jinja2\loaders.py", line 126, in load
    source, filename, uptodate = self.get_source(environment, name)
                                 ~~~~~~~~~~~~~~~^^^^^^^^^^^^^^^^^^^
  File "C:\Users\Personal\AppData\Roaming\Python\Python313\site-packages\flask\templating.py", line 65, in get_source
    return self._get_source_fast(environment, template)
           ~~~~~~~~~~~~~~~~~~~~~^^^^^^^^^^^^^^^^^^^^^^^
  File "C:\Users\Personal\AppData\Roaming\Python\Python313\site-packages\flask\templating.py", line 99, in _get_source_fast
    raise TemplateNotFound(template)
jinja2.exceptions.TemplateNotFound: errors/500.html
2025-05-09 02:39:46,177 - INFO - 127.0.0.1 - - [09/May/2025 02:39:46] "[35m[1mGET /favicon.ico HTTP/1.1[0m" 500 -
2025-05-09 02:39:46,189 - ERROR - Error on request:
Traceback (most recent call last):
  File "C:\Users\Personal\AppData\Roaming\Python\Python313\site-packages\flask\app.py", line 917, in full_dispatch_request
    rv = self.dispatch_request()
  File "C:\Users\Personal\AppData\Roaming\Python\Python313\site-packages\flask\app.py", line 891, in dispatch_request
    self.raise_routing_exception(req)
    ~~~~~~~~~~~~~~~~~~~~~~~~~~~~^^^^^
  File "C:\Users\Personal\AppData\Roaming\Python\Python313\site-packages\flask\app.py", line 500, in raise_routing_exception
    raise request.routing_exception  # type: ignore[misc]
    ^^^^^^^^^^^^^^^^^^^^^^^^^^^^^^^
  File "C:\Users\Personal\AppData\Roaming\Python\Python313\site-packages\flask\ctx.py", line 362, in match_request
    result = self.url_adapter.match(return_rule=True)  # type: ignore
  File "C:\Users\Personal\AppData\Roaming\Python\Python313\site-packages\werkzeug\routing\map.py", line 629, in match
    raise NotFound() from None
werkzeug.exceptions.NotFound: 404 Not Found: The requested URL was not found on the server. If you entered the URL manually please check your spelling and try again.

During handling of the above exception, another exception occurred:

Traceback (most recent call last):
  File "C:\Users\Personal\AppData\Roaming\Python\Python313\site-packages\flask\app.py", line 1511, in wsgi_app
    response = self.full_dispatch_request()
  File "C:\Users\Personal\AppData\Roaming\Python\Python313\site-packages\flask\app.py", line 919, in full_dispatch_request
    rv = self.handle_user_exception(e)
  File "C:\Users\Personal\AppData\Roaming\Python\Python313\site-packages\flask\app.py", line 802, in handle_user_exception
    return self.handle_http_exception(e)
           ~~~~~~~~~~~~~~~~~~~~~~~~~~^^^
  File "C:\Users\Personal\AppData\Roaming\Python\Python313\site-packages\flask\app.py", line 777, in handle_http_exception
    return self.ensure_sync(handler)(e)  # type: ignore[no-any-return]
           ~~~~~~~~~~~~~~~~~~~~~~~~~^^^
  File "D:\Arsalan khan\ARSALAN KHAN (UNI)\a semester 6 spring 2025\secure software design\project\-Ride-Hailing-Website-with-Integrated-Security-Features\week4-6\app.py", line 558, in page_not_found
    return render_template('errors/404.html'), 404
           ~~~~~~~~~~~~~~~^^^^^^^^^^^^^^^^^^^
  File "C:\Users\Personal\AppData\Roaming\Python\Python313\site-packages\flask\templating.py", line 149, in render_template
    template = app.jinja_env.get_or_select_template(template_name_or_list)
  File "C:\Users\Personal\AppData\Roaming\Python\Python313\site-packages\jinja2\environment.py", line 1087, in get_or_select_template
    return self.get_template(template_name_or_list, parent, globals)
           ~~~~~~~~~~~~~~~~~^^^^^^^^^^^^^^^^^^^^^^^^^^^^^^^^^^^^^^^^
  File "C:\Users\Personal\AppData\Roaming\Python\Python313\site-packages\jinja2\environment.py", line 1016, in get_template
    return self._load_template(name, globals)
           ~~~~~~~~~~~~~~~~~~~^^^^^^^^^^^^^^^
  File "C:\Users\Personal\AppData\Roaming\Python\Python313\site-packages\jinja2\environment.py", line 975, in _load_template
    template = self.loader.load(self, name, self.make_globals(globals))
  File "C:\Users\Personal\AppData\Roaming\Python\Python313\site-packages\jinja2\loaders.py", line 126, in load
    source, filename, uptodate = self.get_source(environment, name)
                                 ~~~~~~~~~~~~~~~^^^^^^^^^^^^^^^^^^^
  File "C:\Users\Personal\AppData\Roaming\Python\Python313\site-packages\flask\templating.py", line 65, in get_source
    return self._get_source_fast(environment, template)
           ~~~~~~~~~~~~~~~~~~~~~^^^^^^^^^^^^^^^^^^^^^^^
  File "C:\Users\Personal\AppData\Roaming\Python\Python313\site-packages\flask\templating.py", line 99, in _get_source_fast
    raise TemplateNotFound(template)
jinja2.exceptions.TemplateNotFound: errors/404.html

During handling of the above exception, another exception occurred:

Traceback (most recent call last):
  File "C:\Users\Personal\AppData\Roaming\Python\Python313\site-packages\werkzeug\serving.py", line 370, in run_wsgi
    execute(self.server.app)
    ~~~~~~~^^^^^^^^^^^^^^^^^
  File "C:\Users\Personal\AppData\Roaming\Python\Python313\site-packages\werkzeug\serving.py", line 331, in execute
    application_iter = app(environ, start_response)
  File "C:\Users\Personal\AppData\Roaming\Python\Python313\site-packages\flask\app.py", line 1536, in __call__
    return self.wsgi_app(environ, start_response)
           ~~~~~~~~~~~~~^^^^^^^^^^^^^^^^^^^^^^^^^
  File "C:\Users\Personal\AppData\Roaming\Python\Python313\site-packages\werkzeug\middleware\proxy_fix.py", line 183, in __call__
    return self.app(environ, start_response)
           ~~~~~~~~^^^^^^^^^^^^^^^^^^^^^^^^^
  File "C:\Users\Personal\AppData\Roaming\Python\Python313\site-packages\flask\app.py", line 1514, in wsgi_app
    response = self.handle_exception(e)
  File "C:\Users\Personal\AppData\Roaming\Python\Python313\site-packages\flask\app.py", line 860, in handle_exception
    server_error = self.ensure_sync(handler)(server_error)
  File "D:\Arsalan khan\ARSALAN KHAN (UNI)\a semester 6 spring 2025\secure software design\project\-Ride-Hailing-Website-with-Integrated-Security-Features\week4-6\app.py", line 562, in internal_server_error
    return render_template('errors/500.html'), 500
           ~~~~~~~~~~~~~~~^^^^^^^^^^^^^^^^^^^
  File "C:\Users\Personal\AppData\Roaming\Python\Python313\site-packages\flask\templating.py", line 149, in render_template
    template = app.jinja_env.get_or_select_template(template_name_or_list)
  File "C:\Users\Personal\AppData\Roaming\Python\Python313\site-packages\jinja2\environment.py", line 1087, in get_or_select_template
    return self.get_template(template_name_or_list, parent, globals)
           ~~~~~~~~~~~~~~~~~^^^^^^^^^^^^^^^^^^^^^^^^^^^^^^^^^^^^^^^^
  File "C:\Users\Personal\AppData\Roaming\Python\Python313\site-packages\jinja2\environment.py", line 1016, in get_template
    return self._load_template(name, globals)
           ~~~~~~~~~~~~~~~~~~~^^^^^^^^^^^^^^^
  File "C:\Users\Personal\AppData\Roaming\Python\Python313\site-packages\jinja2\environment.py", line 975, in _load_template
    template = self.loader.load(self, name, self.make_globals(globals))
  File "C:\Users\Personal\AppData\Roaming\Python\Python313\site-packages\jinja2\loaders.py", line 126, in load
    source, filename, uptodate = self.get_source(environment, name)
                                 ~~~~~~~~~~~~~~~^^^^^^^^^^^^^^^^^^^
  File "C:\Users\Personal\AppData\Roaming\Python\Python313\site-packages\flask\templating.py", line 65, in get_source
    return self._get_source_fast(environment, template)
           ~~~~~~~~~~~~~~~~~~~~~^^^^^^^^^^^^^^^^^^^^^^^
  File "C:\Users\Personal\AppData\Roaming\Python\Python313\site-packages\flask\templating.py", line 99, in _get_source_fast
    raise TemplateNotFound(template)
jinja2.exceptions.TemplateNotFound: errors/500.html
2025-05-09 02:41:40,904 - ERROR - Exception on /login [POST]
Traceback (most recent call last):
  File "C:\Users\Personal\AppData\Roaming\Python\Python313\site-packages\flask\app.py", line 1511, in wsgi_app
    response = self.full_dispatch_request()
  File "C:\Users\Personal\AppData\Roaming\Python\Python313\site-packages\flask\app.py", line 919, in full_dispatch_request
    rv = self.handle_user_exception(e)
  File "C:\Users\Personal\AppData\Roaming\Python\Python313\site-packages\flask\app.py", line 917, in full_dispatch_request
    rv = self.dispatch_request()
  File "C:\Users\Personal\AppData\Roaming\Python\Python313\site-packages\flask\app.py", line 902, in dispatch_request
    return self.ensure_sync(self.view_functions[rule.endpoint])(**view_args)  # type: ignore[no-any-return]
           ~~~~~~~~~~~~~~~~~~~~~~~~~~~~~~~~~~~~~~~~~~~~~~~~~~~~^^^^^^^^^^^^^
  File "D:\Arsalan khan\ARSALAN KHAN (UNI)\a semester 6 spring 2025\secure software design\project\-Ride-Hailing-Website-with-Integrated-Security-Features\week4-6\app.py", line 99, in decorated_function
    return f(*args, **kwargs)
  File "D:\Arsalan khan\ARSALAN KHAN (UNI)\a semester 6 spring 2025\secure software design\project\-Ride-Hailing-Website-with-Integrated-Security-Features\week4-6\app.py", line 172, in login
    user = conn.execute("""
           ~~~~~~~~~~~~^^^^
        SELECT id, email, password, name, role, failed_attempts, locked_until
        ^^^^^^^^^^^^^^^^^^^^^^^^^^^^^^^^^^^^^^^^^^^^^^^^^^^^^^^^^^^^^^^^^^^^^
        FROM users WHERE email = ?
        ^^^^^^^^^^^^^^^^^^^^^^^^^^
    """, (email,)).fetchone()
    ^^^^^^^^^^^^^^
sqlite3.OperationalError: no such column: failed_attempts
2025-05-09 02:41:40,907 - INFO - 127.0.0.1 - - [09/May/2025 02:41:40] "[35m[1mPOST /login HTTP/1.1[0m" 500 -
2025-05-09 02:41:40,922 - ERROR - Error on request:
Traceback (most recent call last):
  File "C:\Users\Personal\AppData\Roaming\Python\Python313\site-packages\flask\app.py", line 1511, in wsgi_app
    response = self.full_dispatch_request()
  File "C:\Users\Personal\AppData\Roaming\Python\Python313\site-packages\flask\app.py", line 919, in full_dispatch_request
    rv = self.handle_user_exception(e)
  File "C:\Users\Personal\AppData\Roaming\Python\Python313\site-packages\flask\app.py", line 917, in full_dispatch_request
    rv = self.dispatch_request()
  File "C:\Users\Personal\AppData\Roaming\Python\Python313\site-packages\flask\app.py", line 902, in dispatch_request
    return self.ensure_sync(self.view_functions[rule.endpoint])(**view_args)  # type: ignore[no-any-return]
           ~~~~~~~~~~~~~~~~~~~~~~~~~~~~~~~~~~~~~~~~~~~~~~~~~~~~^^^^^^^^^^^^^
  File "D:\Arsalan khan\ARSALAN KHAN (UNI)\a semester 6 spring 2025\secure software design\project\-Ride-Hailing-Website-with-Integrated-Security-Features\week4-6\app.py", line 99, in decorated_function
    return f(*args, **kwargs)
  File "D:\Arsalan khan\ARSALAN KHAN (UNI)\a semester 6 spring 2025\secure software design\project\-Ride-Hailing-Website-with-Integrated-Security-Features\week4-6\app.py", line 172, in login
    user = conn.execute("""
           ^^^^^^^
sqlite3.OperationalError: no such column: failed_attempts

During handling of the above exception, another exception occurred:

Traceback (most recent call last):
  File "C:\Users\Personal\AppData\Roaming\Python\Python313\site-packages\werkzeug\serving.py", line 370, in run_wsgi
    execute(self.server.app)
    ~~~~~~~^^^^^^^^^^^^^^^^^
  File "C:\Users\Personal\AppData\Roaming\Python\Python313\site-packages\werkzeug\serving.py", line 331, in execute
    application_iter = app(environ, start_response)
  File "C:\Users\Personal\AppData\Roaming\Python\Python313\site-packages\flask\app.py", line 1536, in __call__
    return self.wsgi_app(environ, start_response)
           ~~~~~~~~~~~~~^^^^^^^^^^^^^^^^^^^^^^^^^
  File "C:\Users\Personal\AppData\Roaming\Python\Python313\site-packages\werkzeug\middleware\proxy_fix.py", line 183, in __call__
    return self.app(environ, start_response)
           ~~~~~~~~^^^^^^^^^^^^^^^^^^^^^^^^^
  File "C:\Users\Personal\AppData\Roaming\Python\Python313\site-packages\flask\app.py", line 1514, in wsgi_app
    response = self.handle_exception(e)
  File "C:\Users\Personal\AppData\Roaming\Python\Python313\site-packages\flask\app.py", line 860, in handle_exception
    server_error = self.ensure_sync(handler)(server_error)
  File "D:\Arsalan khan\ARSALAN KHAN (UNI)\a semester 6 spring 2025\secure software design\project\-Ride-Hailing-Website-with-Integrated-Security-Features\week4-6\app.py", line 562, in internal_server_error
    return render_template('errors/500.html'), 500
           ~~~~~~~~~~~~~~~^^^^^^^^^^^^^^^^^^^
  File "C:\Users\Personal\AppData\Roaming\Python\Python313\site-packages\flask\templating.py", line 149, in render_template
    template = app.jinja_env.get_or_select_template(template_name_or_list)
  File "C:\Users\Personal\AppData\Roaming\Python\Python313\site-packages\jinja2\environment.py", line 1087, in get_or_select_template
    return self.get_template(template_name_or_list, parent, globals)
           ~~~~~~~~~~~~~~~~~^^^^^^^^^^^^^^^^^^^^^^^^^^^^^^^^^^^^^^^^
  File "C:\Users\Personal\AppData\Roaming\Python\Python313\site-packages\jinja2\environment.py", line 1016, in get_template
    return self._load_template(name, globals)
           ~~~~~~~~~~~~~~~~~~~^^^^^^^^^^^^^^^
  File "C:\Users\Personal\AppData\Roaming\Python\Python313\site-packages\jinja2\environment.py", line 975, in _load_template
    template = self.loader.load(self, name, self.make_globals(globals))
  File "C:\Users\Personal\AppData\Roaming\Python\Python313\site-packages\jinja2\loaders.py", line 126, in load
    source, filename, uptodate = self.get_source(environment, name)
                                 ~~~~~~~~~~~~~~~^^^^^^^^^^^^^^^^^^^
  File "C:\Users\Personal\AppData\Roaming\Python\Python313\site-packages\flask\templating.py", line 65, in get_source
    return self._get_source_fast(environment, template)
           ~~~~~~~~~~~~~~~~~~~~~^^^^^^^^^^^^^^^^^^^^^^^
  File "C:\Users\Personal\AppData\Roaming\Python\Python313\site-packages\flask\templating.py", line 99, in _get_source_fast
    raise TemplateNotFound(template)
jinja2.exceptions.TemplateNotFound: errors/500.html
2025-05-09 02:41:40,965 - ERROR - Exception on /favicon.ico [GET]
Traceback (most recent call last):
  File "C:\Users\Personal\AppData\Roaming\Python\Python313\site-packages\flask\app.py", line 917, in full_dispatch_request
    rv = self.dispatch_request()
  File "C:\Users\Personal\AppData\Roaming\Python\Python313\site-packages\flask\app.py", line 891, in dispatch_request
    self.raise_routing_exception(req)
    ~~~~~~~~~~~~~~~~~~~~~~~~~~~~^^^^^
  File "C:\Users\Personal\AppData\Roaming\Python\Python313\site-packages\flask\app.py", line 500, in raise_routing_exception
    raise request.routing_exception  # type: ignore[misc]
    ^^^^^^^^^^^^^^^^^^^^^^^^^^^^^^^
  File "C:\Users\Personal\AppData\Roaming\Python\Python313\site-packages\flask\ctx.py", line 362, in match_request
    result = self.url_adapter.match(return_rule=True)  # type: ignore
  File "C:\Users\Personal\AppData\Roaming\Python\Python313\site-packages\werkzeug\routing\map.py", line 629, in match
    raise NotFound() from None
werkzeug.exceptions.NotFound: 404 Not Found: The requested URL was not found on the server. If you entered the URL manually please check your spelling and try again.

During handling of the above exception, another exception occurred:

Traceback (most recent call last):
  File "C:\Users\Personal\AppData\Roaming\Python\Python313\site-packages\flask\app.py", line 1511, in wsgi_app
    response = self.full_dispatch_request()
  File "C:\Users\Personal\AppData\Roaming\Python\Python313\site-packages\flask\app.py", line 919, in full_dispatch_request
    rv = self.handle_user_exception(e)
  File "C:\Users\Personal\AppData\Roaming\Python\Python313\site-packages\flask\app.py", line 802, in handle_user_exception
    return self.handle_http_exception(e)
           ~~~~~~~~~~~~~~~~~~~~~~~~~~^^^
  File "C:\Users\Personal\AppData\Roaming\Python\Python313\site-packages\flask\app.py", line 777, in handle_http_exception
    return self.ensure_sync(handler)(e)  # type: ignore[no-any-return]
           ~~~~~~~~~~~~~~~~~~~~~~~~~^^^
  File "D:\Arsalan khan\ARSALAN KHAN (UNI)\a semester 6 spring 2025\secure software design\project\-Ride-Hailing-Website-with-Integrated-Security-Features\week4-6\app.py", line 558, in page_not_found
    return render_template('errors/404.html'), 404
           ~~~~~~~~~~~~~~~^^^^^^^^^^^^^^^^^^^
  File "C:\Users\Personal\AppData\Roaming\Python\Python313\site-packages\flask\templating.py", line 149, in render_template
    template = app.jinja_env.get_or_select_template(template_name_or_list)
  File "C:\Users\Personal\AppData\Roaming\Python\Python313\site-packages\jinja2\environment.py", line 1087, in get_or_select_template
    return self.get_template(template_name_or_list, parent, globals)
           ~~~~~~~~~~~~~~~~~^^^^^^^^^^^^^^^^^^^^^^^^^^^^^^^^^^^^^^^^
  File "C:\Users\Personal\AppData\Roaming\Python\Python313\site-packages\jinja2\environment.py", line 1016, in get_template
    return self._load_template(name, globals)
           ~~~~~~~~~~~~~~~~~~~^^^^^^^^^^^^^^^
  File "C:\Users\Personal\AppData\Roaming\Python\Python313\site-packages\jinja2\environment.py", line 975, in _load_template
    template = self.loader.load(self, name, self.make_globals(globals))
  File "C:\Users\Personal\AppData\Roaming\Python\Python313\site-packages\jinja2\loaders.py", line 126, in load
    source, filename, uptodate = self.get_source(environment, name)
                                 ~~~~~~~~~~~~~~~^^^^^^^^^^^^^^^^^^^
  File "C:\Users\Personal\AppData\Roaming\Python\Python313\site-packages\flask\templating.py", line 65, in get_source
    return self._get_source_fast(environment, template)
           ~~~~~~~~~~~~~~~~~~~~~^^^^^^^^^^^^^^^^^^^^^^^
  File "C:\Users\Personal\AppData\Roaming\Python\Python313\site-packages\flask\templating.py", line 99, in _get_source_fast
    raise TemplateNotFound(template)
jinja2.exceptions.TemplateNotFound: errors/404.html
2025-05-09 02:41:40,972 - INFO - 127.0.0.1 - - [09/May/2025 02:41:40] "[35m[1mGET /favicon.ico HTTP/1.1[0m" 500 -
2025-05-09 02:41:40,987 - ERROR - Error on request:
Traceback (most recent call last):
  File "C:\Users\Personal\AppData\Roaming\Python\Python313\site-packages\flask\app.py", line 917, in full_dispatch_request
    rv = self.dispatch_request()
  File "C:\Users\Personal\AppData\Roaming\Python\Python313\site-packages\flask\app.py", line 891, in dispatch_request
    self.raise_routing_exception(req)
    ~~~~~~~~~~~~~~~~~~~~~~~~~~~~^^^^^
  File "C:\Users\Personal\AppData\Roaming\Python\Python313\site-packages\flask\app.py", line 500, in raise_routing_exception
    raise request.routing_exception  # type: ignore[misc]
    ^^^^^^^^^^^^^^^^^^^^^^^^^^^^^^^
  File "C:\Users\Personal\AppData\Roaming\Python\Python313\site-packages\flask\ctx.py", line 362, in match_request
    result = self.url_adapter.match(return_rule=True)  # type: ignore
  File "C:\Users\Personal\AppData\Roaming\Python\Python313\site-packages\werkzeug\routing\map.py", line 629, in match
    raise NotFound() from None
werkzeug.exceptions.NotFound: 404 Not Found: The requested URL was not found on the server. If you entered the URL manually please check your spelling and try again.

During handling of the above exception, another exception occurred:

Traceback (most recent call last):
  File "C:\Users\Personal\AppData\Roaming\Python\Python313\site-packages\flask\app.py", line 1511, in wsgi_app
    response = self.full_dispatch_request()
  File "C:\Users\Personal\AppData\Roaming\Python\Python313\site-packages\flask\app.py", line 919, in full_dispatch_request
    rv = self.handle_user_exception(e)
  File "C:\Users\Personal\AppData\Roaming\Python\Python313\site-packages\flask\app.py", line 802, in handle_user_exception
    return self.handle_http_exception(e)
           ~~~~~~~~~~~~~~~~~~~~~~~~~~^^^
  File "C:\Users\Personal\AppData\Roaming\Python\Python313\site-packages\flask\app.py", line 777, in handle_http_exception
    return self.ensure_sync(handler)(e)  # type: ignore[no-any-return]
           ~~~~~~~~~~~~~~~~~~~~~~~~~^^^
  File "D:\Arsalan khan\ARSALAN KHAN (UNI)\a semester 6 spring 2025\secure software design\project\-Ride-Hailing-Website-with-Integrated-Security-Features\week4-6\app.py", line 558, in page_not_found
    return render_template('errors/404.html'), 404
           ~~~~~~~~~~~~~~~^^^^^^^^^^^^^^^^^^^
  File "C:\Users\Personal\AppData\Roaming\Python\Python313\site-packages\flask\templating.py", line 149, in render_template
    template = app.jinja_env.get_or_select_template(template_name_or_list)
  File "C:\Users\Personal\AppData\Roaming\Python\Python313\site-packages\jinja2\environment.py", line 1087, in get_or_select_template
    return self.get_template(template_name_or_list, parent, globals)
           ~~~~~~~~~~~~~~~~~^^^^^^^^^^^^^^^^^^^^^^^^^^^^^^^^^^^^^^^^
  File "C:\Users\Personal\AppData\Roaming\Python\Python313\site-packages\jinja2\environment.py", line 1016, in get_template
    return self._load_template(name, globals)
           ~~~~~~~~~~~~~~~~~~~^^^^^^^^^^^^^^^
  File "C:\Users\Personal\AppData\Roaming\Python\Python313\site-packages\jinja2\environment.py", line 975, in _load_template
    template = self.loader.load(self, name, self.make_globals(globals))
  File "C:\Users\Personal\AppData\Roaming\Python\Python313\site-packages\jinja2\loaders.py", line 126, in load
    source, filename, uptodate = self.get_source(environment, name)
                                 ~~~~~~~~~~~~~~~^^^^^^^^^^^^^^^^^^^
  File "C:\Users\Personal\AppData\Roaming\Python\Python313\site-packages\flask\templating.py", line 65, in get_source
    return self._get_source_fast(environment, template)
           ~~~~~~~~~~~~~~~~~~~~~^^^^^^^^^^^^^^^^^^^^^^^
  File "C:\Users\Personal\AppData\Roaming\Python\Python313\site-packages\flask\templating.py", line 99, in _get_source_fast
    raise TemplateNotFound(template)
jinja2.exceptions.TemplateNotFound: errors/404.html

During handling of the above exception, another exception occurred:

Traceback (most recent call last):
  File "C:\Users\Personal\AppData\Roaming\Python\Python313\site-packages\werkzeug\serving.py", line 370, in run_wsgi
    execute(self.server.app)
    ~~~~~~~^^^^^^^^^^^^^^^^^
  File "C:\Users\Personal\AppData\Roaming\Python\Python313\site-packages\werkzeug\serving.py", line 331, in execute
    application_iter = app(environ, start_response)
  File "C:\Users\Personal\AppData\Roaming\Python\Python313\site-packages\flask\app.py", line 1536, in __call__
    return self.wsgi_app(environ, start_response)
           ~~~~~~~~~~~~~^^^^^^^^^^^^^^^^^^^^^^^^^
  File "C:\Users\Personal\AppData\Roaming\Python\Python313\site-packages\werkzeug\middleware\proxy_fix.py", line 183, in __call__
    return self.app(environ, start_response)
           ~~~~~~~~^^^^^^^^^^^^^^^^^^^^^^^^^
  File "C:\Users\Personal\AppData\Roaming\Python\Python313\site-packages\flask\app.py", line 1514, in wsgi_app
    response = self.handle_exception(e)
  File "C:\Users\Personal\AppData\Roaming\Python\Python313\site-packages\flask\app.py", line 860, in handle_exception
    server_error = self.ensure_sync(handler)(server_error)
  File "D:\Arsalan khan\ARSALAN KHAN (UNI)\a semester 6 spring 2025\secure software design\project\-Ride-Hailing-Website-with-Integrated-Security-Features\week4-6\app.py", line 562, in internal_server_error
    return render_template('errors/500.html'), 500
           ~~~~~~~~~~~~~~~^^^^^^^^^^^^^^^^^^^
  File "C:\Users\Personal\AppData\Roaming\Python\Python313\site-packages\flask\templating.py", line 149, in render_template
    template = app.jinja_env.get_or_select_template(template_name_or_list)
  File "C:\Users\Personal\AppData\Roaming\Python\Python313\site-packages\jinja2\environment.py", line 1087, in get_or_select_template
    return self.get_template(template_name_or_list, parent, globals)
           ~~~~~~~~~~~~~~~~~^^^^^^^^^^^^^^^^^^^^^^^^^^^^^^^^^^^^^^^^
  File "C:\Users\Personal\AppData\Roaming\Python\Python313\site-packages\jinja2\environment.py", line 1016, in get_template
    return self._load_template(name, globals)
           ~~~~~~~~~~~~~~~~~~~^^^^^^^^^^^^^^^
  File "C:\Users\Personal\AppData\Roaming\Python\Python313\site-packages\jinja2\environment.py", line 975, in _load_template
    template = self.loader.load(self, name, self.make_globals(globals))
  File "C:\Users\Personal\AppData\Roaming\Python\Python313\site-packages\jinja2\loaders.py", line 126, in load
    source, filename, uptodate = self.get_source(environment, name)
                                 ~~~~~~~~~~~~~~~^^^^^^^^^^^^^^^^^^^
  File "C:\Users\Personal\AppData\Roaming\Python\Python313\site-packages\flask\templating.py", line 65, in get_source
    return self._get_source_fast(environment, template)
           ~~~~~~~~~~~~~~~~~~~~~^^^^^^^^^^^^^^^^^^^^^^^
  File "C:\Users\Personal\AppData\Roaming\Python\Python313\site-packages\flask\templating.py", line 99, in _get_source_fast
    raise TemplateNotFound(template)
jinja2.exceptions.TemplateNotFound: errors/500.html
